(window["webpackJsonp"]=window["webpackJsonp"]||[]).push([["tema12"],{"05a2":function(a,t,e){a.exports=e.p+"img/img4.f7e4913b.png"},"433c":function(a,t,e){a.exports=e.p+"img/img2.02ac938f.png"},6454:function(a,t,e){a.exports=e.p+"img/img1.69b715c7.svg"},"870d":function(a,t,e){a.exports=e.p+"img/img11.4d504c36.svg"},b9c3:function(a,t,e){a.exports=e.p+"img/img1.346433dd.png"},c530:function(a,t,e){a.exports=e.p+"img/img3.8939c725.png"},f526:function(a,t,e){"use strict";e.r(t);var s=function(){var a=this,t=a.$createElement,e=a._self._c||t;return e("div",{staticClass:"curso-main-container pb-3"},[e("BannerInterno"),a._m(0)],1)},i=[function(){var a=this,t=a.$createElement,s=a._self._c||t;return s("div",{staticClass:"container tarjeta tarjeta--blanca p-4 p-md-5 mb-5"},[s("div",{staticClass:"titulo-principal color-acento-contenido",attrs:{"data-aos":"flip-up"}},[s("div",{staticClass:"titulo-principal__numero"},[s("span",[a._v("12")])]),s("h1",[a._v("Manejo de errores y excepciones")])]),s("div",{staticClass:"row mb-5"},[s("div",{staticClass:"col-12"},[s("div",{staticClass:"p-4 bg-c6",attrs:{"data-aos":"fade-right"}},[s("div",{staticClass:"row align-items-center"},[s("div",{staticClass:"col-lg-3"},[s("figure",[s("img",{staticClass:"m-auto",staticStyle:{width:"360px"},attrs:{src:e("b9c3"),alt:""}})])]),s("div",{staticClass:"col-lg-9"},[s("div",{staticClass:"p-4 bg-c16"},[s("p",[a._v("Las excepciones son errores imprevistos que ocurren en la ejecución de un programa; son anormalidades que impiden o perturban el comportamiento o el flujo normal de las instrucciones de un programa.")]),s("p",{staticClass:"mb-0"},[s("b",{staticClass:"txt-c1"},[a._v("El objetivo principal en el manejo de errores es separar el código de la lógica del programa del código de manejo de excepciones. De esta forma, al producirse la anomalía, si ocurre un error y existe un manejador de excepciones, él toma el control de la ejecución del programa.")])])])])])])])]),s("p",{staticClass:"mb-5",attrs:{"data-aos":"fade-left"}},[a._v("En JavaScript, el control de errores resulta muy necesario, tal vez más que en otros lenguajes, debido a la dificultad natural para probar aplicaciones o los cambios de versión de intérprete en múltiples navegadores.")]),s("div",{staticClass:"row align-items-center mb-5"},[s("div",{staticClass:"col-lg-9 mb-4 mb-lg-0",attrs:{"data-aos":"fade-right"}},[s("div",{staticClass:"row mb-3"},[s("div",{staticClass:"col-auto"},[s("figure",{staticClass:"mt-1"},[s("img",{staticClass:"m-auto",staticStyle:{width:"70px"},attrs:{src:e("6454"),alt:""}})])]),s("div",{staticClass:"col"},[s("p",{staticClass:"mb-0"},[a._v("La forma más sencilla de disparar un error es con la palabra reservada "),s("b",[a._v("throw")]),a._v(". Este comando permite enviar al intérprete de JavaScript el evento de que ha ocurrido un error, generalmente permite enviar cualquier tipo de dato, pero lo más común es enviar un “Error” como se indica a continuación:")])])]),s("div",{staticClass:"row"},[s("div",{staticClass:"col-12"},[s("div",{staticClass:"px-4 py-3 bg-c22"},[s("figure",[s("img",{staticStyle:{width:"50px"},attrs:{src:e("870d"),alt:""}})])])]),s("div",{staticClass:"col-12"},[s("div",{staticClass:"px-4 py-3 bg-c23"},[s("pre",[s("p",{staticClass:"mb-0"},[a._v(" "),s("span",{staticClass:"txt-c7"},[a._v("throw new")]),a._v(" "),s("span",{staticClass:"txt-c8"},[a._v("Error")]),a._v("("),s("span",{staticClass:"txt-c9"},[a._v('"No se puede dividir por cero"')]),a._v(");")])])])])])]),s("div",{staticClass:"col-lg-3",attrs:{"data-aos":"fade-left"}},[s("figure",[s("img",{staticClass:"m-auto",staticStyle:{width:"360px"},attrs:{src:e("433c"),alt:""}})])])]),s("p",{staticClass:"mb-5",attrs:{"data-aos":"fade-right"}},[a._v("Existe un tipo de estructura de control en JavaScript que está pendiente de revisar en el flujo de ejecución de un programa para detectar comportamientos inesperados. La estructura es "),s("b",[a._v("try...catch")]),a._v(", que consta de un bloque que intenta la ejecución de una sección de código (contexto) a la espera de que pueda ocurrir una posible excepción. Finalizado el contexto, existe otro denominado catch que tiene un argumento o variable de contexto donde se captura el elemento disparado.")]),s("div",{staticClass:"row align-items-center mb-5"},[s("div",{staticClass:"col-lg-6 mb-4 mb-lg-0",attrs:{"data-aos":"fade-right"}},[s("div",{staticClass:"row"},[s("div",{staticClass:"col-12"},[s("div",{staticClass:"px-4 py-3 bg-c22"},[s("figure",[s("img",{staticStyle:{width:"50px"},attrs:{src:e("870d"),alt:""}})])])]),s("div",{staticClass:"col-12"},[s("div",{staticClass:"px-4 py-3 bg-c23"},[s("pre",[s("p",{staticClass:"mb-0"},[a._v(" let numerador = 4;")]),s("p",{staticClass:"mb-0"},[a._v(" let denominador = 0;")]),s("p",{staticClass:"mb-0"},[a._v(" var resultado = null;")]),s("p",{staticClass:"mb-0"},[a._v(" try {")]),s("p",{staticClass:"mb-0"},[a._v("     if (denominador === 0) {")]),s("p",{staticClass:"mb-0"},[a._v('         throw new Error("No se puede dividir por cero");')]),s("p",{staticClass:"mb-0"},[a._v("     } else {")]),s("p",{staticClass:"mb-0"},[a._v("         resultado = numerador / denominador;")]),s("p",{staticClass:"mb-0"},[a._v("     }")]),s("p",{staticClass:"mb-0"},[a._v(" } catch (e) {")]),s("p",{staticClass:"mb-0"},[a._v("     console.error(e);")]),s("p",{staticClass:"mb-0"},[a._v("     resultado = null;")]),s("p",{staticClass:"mb-0"},[a._v(" }")]),s("hr"),s("p",{staticClass:"mb-0"},[a._v(" Consola")]),s("p",{staticClass:"mb-0"},[a._v(" error: Error: No se puede dividir por cero")])])])])])]),s("div",{staticClass:"col-lg-6",attrs:{"data-aos":"fade-left"}},[s("figure",[s("img",{staticClass:"m-auto",staticStyle:{width:"500px"},attrs:{src:e("c530"),alt:""}})])])]),s("p",{staticClass:"mb-5",attrs:{"data-aos":"fade-right"}},[s("b",{staticClass:"txt-c1"},[a._v("En el código se describe un algoritmo que divide dos números y, como se sabe, en este proceso se debe validar que no exista una división por 0, ya que no está definida aritméticamente.")])]),s("div",{staticClass:"row"},[s("div",{staticClass:"col-12"},[s("div",{staticClass:"p-4 bg-c6",attrs:{"data-aos":"fade-left"}},[s("div",{staticClass:"row align-items-center"},[s("div",{staticClass:"col-lg-3"},[s("figure",[s("img",{staticClass:"m-auto",staticStyle:{width:"360px"},attrs:{src:e("05a2"),alt:""}})])]),s("div",{staticClass:"col-lg-9"},[s("div",{staticClass:"p-4 bg-c16"},[s("p",[a._v("Para eso, existe el contexto try que va desde la línea 4 a la línea 10. Dentro de él se verifica el caso de que el divisor, si es igual a 0, debe disparar una excepción. Ella es capturada en la línea 10 por el contexto catch en la variable e. De esta forma, el contexto de catch de la línea 10 a la 13 maneja la excepción, enviando un mensaje de error y asignando a la variable resultado el valor nulo. Así, la excepción es lanzada y capturada, y el programa no se interrumpe "),s("b",{staticClass:"txt-c1"},[a._v("abruptamente, sino que es controlado a pesar de los problemas que se puedan presentar")]),a._v(".")])])])])])])])])}],r={name:"Tema12",data:function(){return{}},mounted:function(){var a=this;this.$nextTick((function(){a.$aosRefresh()}))},updated:function(){this.$aosRefresh()}},c=r,o=e("2877"),l=Object(o["a"])(c,s,i,!1,null,null,null);t["default"]=l.exports}}]);
//# sourceMappingURL=tema12.50a4c65e.js.map